<mujoco model="K1">
  <compiler angle="radian" meshdir="meshes/" autolimits="true"/>

  <worldbody>
    <body name="Trunk" pos="0 0 0.56">
      <site name="imu" size="0.01" pos="0 0 0"/>
      <inertial pos="-0.0043392 -0.00065534 0.065686" quat="0.999896 -0.00411546 0.0137413 -0.00168959" mass="6.5"
        diaginertia="0.0962166 0.0895166 0.0201248"/>
      <joint name="floating_base_joint" type="free"/>

      <body name="Head_1" pos="0.0056 0 0.2149">
        <inertial pos="-0.00069503 -0.00038527 0.031688" mass="0.3"
          diaginertia="0.000429546 0.000420659 0.000125795"/>
        <joint name="AAHead_yaw" pos="0 0 0" axis="0 0 1" range="-1 1"/>
        <body name="Head_2" pos="0 0 0.033">
          <inertial pos="0.011042 -0.00092871 0.080698" mass="0.7"
            diaginertia="0.00603249 0.00577511 0.0017024"/>
          <joint name="Head_pitch" pos="0 0 0" axis="0 1 0" range="-0.349 0.855"/>
        </body>
      </body>

      <body name="Left_Arm_1" pos="0 0.077 0.1845">
        <inertial pos="-0.002701 0.062383 -0.011965" mass="0.5"
          diaginertia="0.00223871 0.00217107 0.000254225"/>
        <joint name="ALeft_Shoulder_Pitch" pos="0 0 0" axis="0 1 0" range="-3.316 1.22"/>
        <body name="Left_Arm_2" pos="0.0025 0.068 -0.0135">
          <inertial pos="0.01729 0.018221 -4.329e-05" mass="0.09"
            diaginertia="0.000113 9.5e-05 6.5e-05"/>
          <joint name="Left_Shoulder_Roll" pos="0 0 0" axis="1 0 0" range="-1.74 1.57"/>
          <body name="Left_Arm_3" pos="0 0.044428 0">
            <inertial pos="-0.0003979 0.072617 -0.00066218" mass="0.8"
              diaginertia="0.00606947 0.00606767 0.000385851"/>
            <joint name="Left_Elbow_Pitch" pos="0 0 0" axis="0 1 0" range="-2.27 2.27"/>
            <body name="left_hand_link" pos="0 0.1215 0">
              <inertial pos="-0.0015751 0.084637 0.0087033" mass="0.19"
                diaginertia="0.00205619 0.00202933 8.1482e-05"/>
              <joint name="Left_Elbow_Yaw" pos="0 0 0" axis="0 0 1" range="-2.44 0"/>
            </body>
          </body>
        </body>
      </body>

      <body name="Right_Arm_1" pos="0 -0.077 0.1845">
        <inertial pos="-0.0026302 -0.06251 -0.01199" mass="0.5"
          diaginertia="0.00224439 0.00217742 0.000255199"/>
        <joint name="ARight_Shoulder_Pitch" pos="0 0 0" axis="0 1 0" range="-3.316 1.22"/>
        <body name="Right_Arm_2" pos="0.0025 -0.068 -0.0135">
          <inertial pos="0.017229 -0.018428 4.3784e-05" mass="0.09"
            diaginertia="0.000113 9.5e-05 6.5e-05"/>
          <joint name="Right_Shoulder_Roll" pos="0 0 0" axis="1 0 0" range="-1.57 1.74"/>
          <body name="Right_Arm_3" pos="0 -0.044428 0">
            <inertial pos="-0.00039919 -0.072601 -0.00065629" mass="0.8"
              diaginertia="0.00607047 0.00606867 0.000386851"/>
            <joint name="Right_Elbow_Pitch" pos="0 0 0" axis="0 1 0" range="-2.27 2.27"/>
            <body name="right_hand_link" pos="0 -0.1215 0">
              <inertial pos="-0.0015177 -0.084536 0.0086733" mass="0.19"
                diaginertia="0.00205618 0.00203032 8.14943e-05"/>
              <joint name="Right_Elbow_Yaw" pos="0 0 0" axis="0 0 1" range="0 2.44"/>
            </body>
          </body>
        </body>
      </body>

      <body name="Left_Hip_Pitch" pos="0 0.096 -0.077">
        <inertial pos="-0.010093 -0.0019934 -0.024713" mass="0.69"
          diaginertia="0.000987585 0.000880963 0.000503452"/>
        <joint name="Left_Hip_Pitch" pos="0 0 0" axis="0 1 0" range="-3 2.21"/>
        <body name="Left_Hip_Roll" pos="0 0 -0.026">
          <inertial pos="0.023585 4.9e-05 -0.024996" mass="0.13"
            diaginertia="0.000262 0.000222694 0.000118306"/>
          <joint name="Left_Hip_Roll" pos="0 0 0" axis="1 0 0" range="-0.4 1.57"/>
          <body name="Left_Hip_Yaw" pos="0.012 0 -0.0485">
            <inertial pos="-0.0084744 -0.0040494 -0.087906" mass="1.65"
              diaginertia="0.0162716 0.0158564 0.00134895"/>
            <joint name="Left_Hip_Yaw" pos="0 0 0" axis="0 0 1" range="-1 1"/>
            <body name="Left_Shank" pos="-0.014 0 -0.117">
              <inertial pos="-0.00081083 0.0031459 -0.10922" mass="1.5"
                diaginertia="0.0237114 0.0236423 0.00123731"/>
              <joint name="Left_Knee_Pitch" pos="0 0 0" axis="0 1 0" range="0 2.23"/>
              <body name="Left_Ankle_Cross" pos="0.00019706 0.0002 -0.24519">
                <inertial pos="0 0 0" mass="0.039"
                  diaginertia="4e-06 4e-06 2e-06"/>
                <joint name="Left_Ankle_Pitch" pos="0 0 0" axis="0 1 0" range="-0.87 0.345"/>
                <body name="left_foot_link">
                  <inertial pos="0.011662 0.000244 -0.014364" mass="0.494"
                    diaginertia="0.0012267 0.00117 0.000247305"/>
                  <joint name="Left_Ankle_Roll" pos="0 0 0" axis="1 0 0" range="-0.345 0.345"/>
                </body>
              </body>
            </body>
          </body>
        </body>
      </body>

      <body name="Right_Hip_Pitch" pos="0 -0.096 -0.077">
        <inertial pos="-0.010065 0.0020086 -0.024739" mass="0.69"
          diaginertia="0.000988671 0.000880749 0.00050458"/>
        <joint name="Right_Hip_Pitch" pos="0 0 0" axis="0 1 0" range="-3 2.21"/>
        <body name="Right_Hip_Roll" pos="0 0 -0.026">
          <inertial pos="0.023585 4.9e-05 -0.024996" mass="0.13"
            diaginertia="0.000262 0.000222694 0.000118306"/>
          <joint name="Right_Hip_Roll" pos="0 0 0" axis="1 0 0" range="-1.57 0.4"/>
          <body name="Right_Hip_Yaw" pos="0.012 0 -0.0485">
            <inertial pos="-0.008475 0.0040392 -0.087906" mass="1.65"
              diaginertia="0.0162716 0.0158564 0.00134895"/>
            <joint name="Right_Hip_Yaw" pos="0 0 0" axis="0 0 1" range="-1 1"/>
            <body name="Right_Shank" pos="-0.014 0 -0.117">
              <inertial pos="-0.000805 -0.003146 -0.109215" mass="1.5"
                diaginertia="0.0237114 0.0236423 0.00123733"/>
              <joint name="Right_Knee_Pitch" pos="0 0 0" axis="0 1 0" range="0 2.23"/>
              <body name="Right_Ankle_Cross" pos="0.00019706 -0.0002 -0.24519">
                <inertial pos="0 0 0" mass="0.039"
                  diaginertia="4e-06 4e-06 2e-06"/>
                <joint name="Right_Ankle_Pitch" pos="0 0 0" axis="0 1 0" range="-0.87 0.345"/>
                <body name="right_foot_link">
                  <inertial pos="0.011662 -0.000244 -0.014364" mass="0.494"
                    diaginertia="0.0012267 0.00117 0.000247305"/>
                  <joint name="Right_Ankle_Roll" pos="0 0 0" axis="1 0 0" range="-0.345 0.345"/>
                </body>
              </body>
            </body>
          </body>
        </body>
      </body>
    </body>
  </worldbody>

  <actuator>
    <position name="AAHead_yaw" joint="AAHead_yaw"/>
    <position name="Head_pitch" joint="Head_pitch"/>
    <position name="ALeft_Shoulder_Pitch" joint="ALeft_Shoulder_Pitch"/>
    <position name="Left_Shoulder_Roll" joint="Left_Shoulder_Roll"/>
    <position name="Left_Elbow_Pitch" joint="Left_Elbow_Pitch"/>
    <position name="Left_Elbow_Yaw" joint="Left_Elbow_Yaw"/>
    <position name="ARight_Shoulder_Pitch" joint="ARight_Shoulder_Pitch"/>
    <position name="Right_Shoulder_Roll" joint="Right_Shoulder_Roll"/>
    <position name="Right_Elbow_Pitch" joint="Right_Elbow_Pitch"/>
    <position name="Right_Elbow_Yaw" joint="Right_Elbow_Yaw"/>
    <position name="Left_Hip_Pitch" joint="Left_Hip_Pitch"/>
    <position name="Left_Hip_Roll" joint="Left_Hip_Roll"/>
    <position name="Left_Hip_Yaw" joint="Left_Hip_Yaw"/>
    <position name="Left_Knee_Pitch" joint="Left_Knee_Pitch"/>
    <position name="Left_Ankle_Pitch" joint="Left_Ankle_Pitch"/>
    <position name="Left_Ankle_Roll" joint="Left_Ankle_Roll"/>
    <position name="Right_Hip_Pitch" joint="Right_Hip_Pitch"/>
    <position name="Right_Hip_Roll" joint="Right_Hip_Roll"/>
    <position name="Right_Hip_Yaw" joint="Right_Hip_Yaw"/>
    <position name="Right_Knee_Pitch" joint="Right_Knee_Pitch"/>
    <position name="Right_Ankle_Pitch" joint="Right_Ankle_Pitch"/>
    <position name="Right_Ankle_Roll" joint="Right_Ankle_Roll"/>
  </actuator>

  <sensor>
    <gyro name="imu-angular-velocity" site="imu" noise="5e-4" cutoff="34.9"/>
    <accelerometer name="imu-linear-acceleration" site="imu" noise="1e-2" cutoff="157"/>
  </sensor>

  <keyframe>
    <key name="home"
      qpos="0 0 0.56 1 0 0 0 0 0 0 0 0 0 0 0 0 0 -0.28 0 0 0.56 -0.28 0 -0.28 0 0 0.56 -0.28 0"/>
  </keyframe>
</mujoco>
